Workbook

Sheet Calculadora
A1: Calculadora de sample size y poder: experimento de crédito por score
A2: Celdas azules con fondo amarillo = edítalas con tu data. Todo lo demás son fórmulas. Los valores actuales son EJEMPLOS, reemplázalos. El cálculo nunca usa más usuarios que tu tope.
A4: PARÁMETROS GENERALES | B4: Valor | E4: Qué es
A5: Alpha (riesgo de falso positivo) | B5: 0.05 | E5: Estándar 0.05.
A6: Poder estadístico objetivo | B6: 0.8 | E6: Estándar 0.80 (80% de probabilidad de detectar un efecto real).
A7: Número de comparaciones (tiers probados) | B7: 3 | E7: 3 si pruebas Excelente, Bueno y Bajo. Pon 1 si pruebas solo uno.
A8: Pérdidas / inactivos | B8: 0.05 | E8: Se descuenta de tus usuarios (los que no activan o salen). Ej. 5%.
A9: Alpha ajustado (Bonferroni) | B9: =B5/B7 -> 0.016666667 | E9: Alpha / número de comparaciones.
A10: z de alpha | B10: =NORMSINV(1-B9/2) -> 2.3939798 | E10: Valor crítico de la normal (dos colas).
A11: z de poder | B11: =NORMSINV(B6) -> 0.84162123 | E11: Valor de la normal para el poder elegido.
A13: DATOS POR TIER (tú los llenas) | B13: Excelente | C13: Bueno | D13: Bajo | E13: Qué poner
A14: Crédito nuevo (MXN) | B14: 1000 | C14: 750 | D14: 250 | E14: Lo que recibirá el tier en el experimento. Hoy todos tienen 500.
A15: MÁXIMO de referidores disponibles en el tier (tope) | B15: 10000 | C15: 10000 | D15: 10000 | E15: El máximo que de verdad existe en el tier. Solo valida que no uses más de lo que hay.
A16: Usuarios en TRATAMIENTO (nuevo crédito) | B16: 5000 | C16: 5000 | D16: 5000 | E16: Cuántos referidores recibirán el crédito nuevo. Escríbelo tú. Tratamiento + control no deben pasar del tope.
A17: Usuarios en CONTROL (se quedan en 500 MXN) | B17: 5000 | C17: 5000 | D17: 5000 | E17: Cuántos referidores se quedan en 500 MXN para comparar. Lo más eficiente es igual que tratamiento.
A18: Loans nuevos al mes del tier (con 500 MXN) | B18: 500 | C18: 300 | D18: 100 | E18: Referidos que obtuvieron loan en el último mes en ese tier. Dato del programa actual.
A19: Meses de ventana de medición | B19: 1 | C19: 1 | D19: 1 | E19: Cuánto tiempo mides a cada usuario. Más meses = tasa más alta = más poder.
A20: Lift relativo esperado entre quienes usan el crédito | B20: 0.3 | C20: 0.15 | D20: -0.15 | E20: Cuánto crees que cambia la tasa. Positivo si el crédito sube, negativo si baja (Bajo).
A21: Take-up (% que usa el crédito) | B21: 0.6 | C21: 0.6 | D21: 0.6 | E21: % de quienes reciben el crédito que realmente lo usa. Diluye el efecto.
A23: RESULTADOS CON TUS USUARIOS | B23: Excelente | C23: Bueno | D23: Bajo | E23: Cómo leerlo
A24: Tasa base mensual (loans / tope) | B24: =B18/B15 -> 0.05 | C24: =C18/C15 -> 0.03 | D24: =D18/D15 -> 0.01 | E24: Aproximación: asume 1 loan por referidor al mes.
A25: Tasa base en la ventana (p1) | B25: =1-(1-B24)^B19 -> 0.05 | C25: =1-(1-C24)^C19 -> 0.03 | D25: =1-(1-D24)^D19 -> 0.01 | E25: Probabilidad de que un referidor traiga un loan en toda la ventana.
A26: Lift efectivo en todo el grupo (ITT) | B26: =B20*B21 -> 0.18 | C26: =C20*C21 -> 0.09 | D26: =D20*D21 -> -0.09 | E26: Lift relativo × take-up. Es el efecto que de verdad se mide.
A27: Tasa esperada con tratamiento (p2) | B27: =B25*(1+B26) -> 0.059 | C27: =C25*(1+C26) -> 0.0327 | D27: =D25*(1+D26) -> 0.0091 | E27: Tasa base ajustada por el lift efectivo.
A28: Usuarios efectivos en tratamiento | B28: =B44 -> 4750 | C28: =C44 -> 4750 | D28: =D44 -> 4750 | E28: Tus usuarios en tratamiento menos pérdidas.
A29: Usuarios efectivos en control (500 MXN) | B29: =B45 -> 4750 | C29: =C45 -> 4750 | D29: =D45 -> 4750 | E29: Tus usuarios en control menos pérdidas.
A30: ¿Tratamiento + control caben en el tope? | B30: =IF(B16+B17<=B15,"Sí: "&TEXT(B16+B17,"#,##0")&" de "&TEXT(B15,"#,##0"),"NO: usas "&TEXT(B16+B17,"#,##0")&" y solo hay "&TEXT(B15,"#,##0")) -> Sí: 10,000 de 10,000 | C30: =IF(C16+C17<=C15,"Sí: "&TEXT(C16+C17,"#,##0")&" de "&TEXT(C15,"#,##0"),"NO: usas "&TEXT(C16+C17,"#,##0")&" y solo hay "&TEXT(C15,"#,##0")) -> Sí: 10,000 de 10,000 | D30: =IF(D16+D17<=D15,"Sí: "&TEXT(D16+D17,"#,##0")&" de "&TEXT(D15,"#,##0"),"NO: usas "&TEXT(D16+D17,"#,##0")&" y solo hay "&TEXT(D15,"#,##0")) -> Sí: 10,000 de 10,000 | E30: Verde = no usas más referidores de los que existen.
A31: PODER real con tus usuarios | B31: =NORMSDIST((ABS(B27-B25)-$B$10*SQRT(B46*(1-B46)*(1/B45+1/B44)))/SQRT(B25*(1-B25)/B45+B27*(1-B27)/B44)) -> 0.32207626 | C31: =NORMSDIST((ABS(C27-C25)-$B$10*SQRT(C46*(1-C46)*(1/C45+1/C44)))/SQRT(C25*(1-C25)/C45+C27*(1-C27)/C44)) -> 0.050612013 | D31: =NORMSDIST((ABS(D27-D25)-$B$10*SQRT(D46*(1-D46)*(1/D45+1/D44)))/SQRT(D25*(1-D25)/D45+D27*(1-D27)/D44)) -> 0.026006776 | E31: Probabilidad de detectar el lift esperado con tus usuarios. Busca 80% o más.
A32: Efecto mínimo detectable relativo (todo el grupo) | B32: =B51/B25 -> 0.30968621 | C32: =C51/C25 -> 0.41331818 | D32: =D51/D25 -> 0.77670174 | E32: Con tus usuarios solo detectas cambios de este tamaño o mayores en la tasa base.
A33: Efecto mínimo detectable entre quienes usan el crédito | B33: =B32/B21 -> 0.51614369 | C33: =C32/C21 -> 0.68886364 | D33: =D32/D21 -> 1.2945029 | E33: Lo mismo, corregido por take-up. Compáralo con el lift que esperas.
A34: ¿Detecta el lift esperado? | B34: =IF(B31>=$B$6,"SÍ","NO") -> NO | C34: =IF(C31>=$B$6,"SÍ","NO") -> NO | D34: =IF(D31>=$B$6,"SÍ","NO") -> NO | E34: SÍ = con tus usuarios llegas al poder objetivo.
A36: REFERENCIA: lo que necesitarías | B36: Excelente | C36: Bueno | D36: Bajo | E36: Cómo leerlo
A37: Usuarios totales que harían falta (con pérdidas) | B37: =IF(B26=0,"n/a",ROUNDUP((((($B$10*SQRT(((B25+B43*B27)/(1+B43))*(1-((B25+B43*B27)/(1+B43)))*(1+1/B43))+$B$11*SQRT(B25*(1-B25)+B27*(1-B27)/B43))^2)/(B27-B25)^2)*(1+B43))/(1-$B$8),0)) -> 28040 | C37: =IF(C26=0,"n/a",ROUNDUP((((($B$10*SQRT(((C25+C43*C27)/(1+C43))*(1-((C25+C43*C27)/(1+C43)))*(1+1/C43))+$B$11*SQRT(C25*(1-C25)+C27*(1-C27)/C43))^2)/(C27-C25)^2)*(1+C43))/(1-$B$8),0)) -> 183619 | D37: =IF(D26=0,"n/a",ROUNDUP((((($B$10*SQRT(((D25+D43*D27)/(1+D43))*(1-((D25+D43*D27)/(1+D43)))*(1+1/D43))+$B$11*SQRT(D25*(1-D25)+D27*(1-D27)/D43))^2)/(D27-D25)^2)*(1+D43))/(1-$B$8),0)) -> 514749 | E37: Para detectar el lift esperado con el poder objetivo y tu proporción tratamiento/control. Es solo referencia.
A38: ¿Cabe en tu tope? | B38: =IF(ISNUMBER(B37),IF(B37<=B15,"Sí cabe en tu tope","No cabe: faltan "&TEXT(B37-B15,"#,##0")),"n/a") -> No cabe: faltan 18,040 | C38: =IF(ISNUMBER(C37),IF(C37<=C15,"Sí cabe en tu tope","No cabe: faltan "&TEXT(C37-C15,"#,##0")),"n/a") -> No cabe: faltan 173,619 | D38: =IF(ISNUMBER(D37),IF(D37<=D15,"Sí cabe en tu tope","No cabe: faltan "&TEXT(D37-D15,"#,##0")),"n/a") -> No cabe: faltan 504,749 | E38: Compara lo necesario contra el máximo que tienes.
A39: Meses de ventana para llegar al poder con tus usuarios | B39: =IF(COUNTIF(B55:B66,">="&$B$6)=0,">12",COUNTIF(B55:B66,"<"&$B$6)+1) -> 3 | C39: =IF(COUNTIF(C55:C66,">="&$B$6)=0,">12",COUNTIF(C55:C66,"<"&$B$6)+1) -> >12 | D39: =IF(COUNTIF(D55:D66,">="&$B$6)=0,">12",COUNTIF(D55:D66,"<"&$B$6)+1) -> >12 | E39: Con tus usuarios y tu lift, cuántos meses mediría cada usuario para llegar a 80% (máx. 12). Asume meses independientes.
A40: Recomendación | B40: =IF(B34="SÍ","Corre el experimento con tus usuarios.",IF(ISNUMBER(B39),"Alarga la ventana a "&B39&" meses.","No alcanza ni a 12 meses: prueba menos tiers o espera un lift mayor.")) -> Alarga la ventana a 3 meses. | C40: =IF(C34="SÍ","Corre el experimento con tus usuarios.",IF(ISNUMBER(C39),"Alarga la ventana a "&C39&" meses.","No alcanza ni a 12 meses: prueba menos tiers o espera un lift mayor.")) -> No alcanza ni a 12 meses: prueba menos tiers o espera un lift mayor. | D40: =IF(D34="SÍ","Corre el experimento con tus usuarios.",IF(ISNUMBER(D39),"Alarga la ventana a "&D39&" meses.","No alcanza ni a 12 meses: prueba menos tiers o espera un lift mayor.")) -> No alcanza ni a 12 meses: prueba menos tiers o espera un lift mayor. | E40: Qué hacer con este tier.
A42: CÁLCULO AUXILIAR (aquí no se escribe: cambia los datos de arriba) | B42: Excelente | C42: Bueno | D42: Bajo | E42: Para qué sirve
A43: k = tratamiento / control | B43: =B16/B17 -> 1 | C43: =C16/C17 -> 1 | D43: =D16/D17 -> 1 | E43: Razón entre grupos.
A44: n efectivo tratamiento | B44: =B16*(1-$B$8) -> 4750 | C44: =C16*(1-$B$8) -> 4750 | D44: =D16*(1-$B$8) -> 4750 | E44: Usuarios en tratamiento × (1 - pérdidas).
A45: n efectivo control | B45: =B17*(1-$B$8) -> 4750 | C45: =C17*(1-$B$8) -> 4750 | D45: =D17*(1-$B$8) -> 4750 | E45: Usuarios en control × (1 - pérdidas).
...

Sheet Tabla_n
A1: Usuarios necesarios por brazo según tasa base y lift (referencia, 50/50)
A2: Usa el alpha, poder y comparaciones de la hoja Calculadora. Es solo referencia: compara contra tu tope. Edita los valores azules para cambiar la rejilla.
A3: Take-up para esta tabla | B3: 1 | C3: 100% = todos usan el crédito. Baja el valor para ver el efecto de la dilución.
A5: Tasa base \ Lift relativo entre quienes usan | B5: 0.1 | C5: 0.15 | D5: 0.2 | E5: 0.3 | F5: 0.5
A6: 0.01 | B6: =ROUNDUP(((Calculadora!$B$10*SQRT(2*(($A6+($A6*(1+B$5*$B$3)))/2)*(1-(($A6+($A6*(1+B$5*$B$3)))/2)))+Calculadora!$B$11*SQRT($A6*(1-$A6)+($A6*(1+B$5*$B$3))*(1-($A6*(1+B$5*$B$3)))))^2)/(($A6*(1+B$5*$B$3))-$A6)^2,0) -> 217542 | C6: =ROUNDUP(((Calculadora!$B$10*SQRT(2*(($A6+($A6*(1+C$5*$B$3)))/2)*(1-(($A6+($A6*(1+C$5*$B$3)))/2)))+Calculadora!$B$11*SQRT($A6*(1-$A6)+($A6*(1+C$5*$B$3))*(1-($A6*(1+C$5*$B$3)))))^2)/(($A6*(1+C$5*$B$3))-$A6)^2,0) -> 98962 | D6: =ROUNDUP(((Calculadora!$B$10*SQRT(2*(($A6+($A6*(1+D$5*$B$3)))/2)*(1-(($A6+($A6*(1+D$5*$B$3)))/2)))+Calculadora!$B$11*SQRT($A6*(1-$A6)+($A6*(1+D$5*$B$3))*(1-($A6*(1+D$5*$B$3)))))^2)/(($A6*(1+D$5*$B$3))-$A6)^2,0) -> 56946 | E6: =ROUNDUP(((Calculadora!$B$10*SQRT(2*(($A6+($A6*(1+E$5*$B$3)))/2)*(1-(($A6+($A6*(1+E$5*$B$3)))/2)))+Calculadora!$B$11*SQRT($A6*(1-$A6)+($A6*(1+E$5*$B$3))*(1-($A6*(1+E$5*$B$3)))))^2)/(($A6*(1+E$5*$B$3))-$A6)^2,0) -> 26446 | F6: =ROUNDUP(((Calculadora!$B$10*SQRT(2*(($A6+($A6*(1+F$5*$B$3)))/2)*(1-(($A6+($A6*(1+F$5*$B$3)))/2)))+Calculadora!$B$11*SQRT($A6*(1-$A6)+($A6*(1+F$5*$B$3))*(1-($A6*(1+F$5*$B$3)))))^2)/(($A6*(1+F$5*$B$3))-$A6)^2,0) -> 10337
A7: 0.02 | B7: =ROUNDUP(((Calculadora!$B$10*SQRT(2*(($A7+($A7*(1+B$5*$B$3)))/2)*(1-(($A7+($A7*(1+B$5*$B$3)))/2)))+Calculadora!$B$11*SQRT($A7*(1-$A7)+($A7*(1+B$5*$B$3))*(1-($A7*(1+B$5*$B$3)))))^2)/(($A7*(1+B$5*$B$3))-$A7)^2,0) -> 107616 | C7: =ROUNDUP(((Calculadora!$B$10*SQRT(2*(($A7+($A7*(1+C$5*$B$3)))/2)*(1-(($A7+($A7*(1+C$5*$B$3)))/2)))+Calculadora!$B$11*SQRT($A7*(1-$A7)+($A7*(1+C$5*$B$3))*(1-($A7*(1+C$5*$B$3)))))^2)/(($A7*(1+C$5*$B$3))-$A7)^2,0) -> 48943 | D7: =ROUNDUP(((Calculadora!$B$10*SQRT(2*(($A7+($A7*(1+D$5*$B$3)))/2)*(1-(($A7+($A7*(1+D$5*$B$3)))/2)))+Calculadora!$B$11*SQRT($A7*(1-$A7)+($A7*(1+D$5*$B$3))*(1-($A7*(1+D$5*$B$3)))))^2)/(($A7*(1+D$5*$B$3))-$A7)^2,0) -> 28156 | E7: =ROUNDUP(((Calculadora!$B$10*SQRT(2*(($A7+($A7*(1+E$5*$B$3)))/2)*(1-(($A7+($A7*(1+E$5*$B$3)))/2)))+Calculadora!$B$11*SQRT($A7*(1-$A7)+($A7*(1+E$5*$B$3))*(1-($A7*(1+E$5*$B$3)))))^2)/(($A7*(1+E$5*$B$3))-$A7)^2,0) -> 13069 | F7: =ROUNDUP(((Calculadora!$B$10*SQRT(2*(($A7+($A7*(1+F$5*$B$3)))/2)*(1-(($A7+($A7*(1+F$5*$B$3)))/2)))+Calculadora!$B$11*SQRT($A7*(1-$A7)+($A7*(1+F$5*$B$3))*(1-($A7*(1+F$5*$B$3)))))^2)/(($A7*(1+F$5*$B$3))-$A7)^2,0) -> 5103
A8: 0.03 | B8: =ROUNDUP(((Calculadora!$B$10*SQRT(2*(($A8+($A8*(1+B$5*$B$3)))/2)*(1-(($A8+($A8*(1+B$5*$B$3)))/2)))+Calculadora!$B$11*SQRT($A8*(1-$A8)+($A8*(1+B$5*$B$3))*(1-($A8*(1+B$5*$B$3)))))^2)/(($A8*(1+B$5*$B$3))-$A8)^2,0) -> 70974 | C8: =ROUNDUP(((Calculadora!$B$10*SQRT(2*(($A8+($A8*(1+C$5*$B$3)))/2)*(1-(($A8+($A8*(1+C$5*$B$3)))/2)))+Calculadora!$B$11*SQRT($A8*(1-$A8)+($A8*(1+C$5*$B$3))*(1-($A8*(1+C$5*$B$3)))))^2)/(($A8*(1+C$5*$B$3))-$A8)^2,0) -> 32270 | D8: =ROUNDUP(((Calculadora!$B$10*SQRT(2*(($A8+($A8*(1+D$5*$B$3)))/2)*(1-(($A8+($A8*(1+D$5*$B$3)))/2)))+Calculadora!$B$11*SQRT($A8*(1-$A8)+($A8*(1+D$5*$B$3))*(1-($A8*(1+D$5*$B$3)))))^2)/(($A8*(1+D$5*$B$3))-$A8)^2,0) -> 18559 | E8: =ROUNDUP(((Calculadora!$B$10*SQRT(2*(($A8+($A8*(1+E$5*$B$3)))/2)*(1-(($A8+($A8*(1+E$5*$B$3)))/2)))+Calculadora!$B$11*SQRT($A8*(1-$A8)+($A8*(1+E$5*$B$3))*(1-($A8*(1+E$5*$B$3)))))^2)/(($A8*(1+E$5*$B$3))-$A8)^2,0) -> 8610 | F8: =ROUNDUP(((Calculadora!$B$10*SQRT(2*(($A8+($A8*(1+F$5*$B$3)))/2)*(1-(($A8+($A8*(1+F$5*$B$3)))/2)))+Calculadora!$B$11*SQRT($A8*(1-$A8)+($A8*(1+F$5*$B$3))*(1-($A8*(1+F$5*$B$3)))))^2)/(($A8*(1+F$5*$B$3))-$A8)^2,0) -> 3358
A9: 0.05 | B9: =ROUNDUP(((Calculadora!$B$10*SQRT(2*(($A9+($A9*(1+B$5*$B$3)))/2)*(1-(($A9+($A9*(1+B$5*$B$3)))/2)))+Calculadora!$B$11*SQRT($A9*(1-$A9)+($A9*(1+B$5*$B$3))*(1-($A9*(1+B$5*$B$3)))))^2)/(($A9*(1+B$5*$B$3))-$A9)^2,0) -> 41661 | C9: =ROUNDUP(((Calculadora!$B$10*SQRT(2*(($A9+($A9*(1+C$5*$B$3)))/2)*(1-(($A9+($A9*(1+C$5*$B$3)))/2)))+Calculadora!$B$11*SQRT($A9*(1-$A9)+($A9*(1+C$5*$B$3))*(1-($A9*(1+C$5*$B$3)))))^2)/(($A9*(1+C$5*$B$3))-$A9)^2,0) -> 18931 | D9: =ROUNDUP(((Calculadora!$B$10*SQRT(2*(($A9+($A9*(1+D$5*$B$3)))/2)*(1-(($A9+($A9*(1+D$5*$B$3)))/2)))+Calculadora!$B$11*SQRT($A9*(1-$A9)+($A9*(1+D$5*$B$3))*(1-($A9*(1+D$5*$B$3)))))^2)/(($A9*(1+D$5*$B$3))-$A9)^2,0) -> 10882 | E9: =ROUNDUP(((Calculadora!$B$10*SQRT(2*(($A9+($A9*(1+E$5*$B$3)))/2)*(1-(($A9+($A9*(1+E$5*$B$3)))/2)))+Calculadora!$B$11*SQRT($A9*(1-$A9)+($A9*(1+E$5*$B$3))*(1-($A9*(1+E$5*$B$3)))))^2)/(($A9*(1+E$5*$B$3))-$A9)^2,0) -> 5042 | F9: =ROUNDUP(((Calculadora!$B$10*SQRT(2*(($A9+($A9*(1+F$5*$B$3)))/2)*(1-(($A9+($A9*(1+F$5*$B$3)))/2)))+Calculadora!$B$11*SQRT($A9*(1-$A9)+($A9*(1+F$5*$B$3))*(1-($A9*(1+F$5*$B$3)))))^2)/(($A9*(1+F$5*$B$3))-$A9)^2,0) -> 1962
A10: 0.08 | B10: =ROUNDUP(((Calculadora!$B$10*SQRT(2*(($A10+($A10*(1+B$5*$B$3)))/2)*(1-(($A10+($A10*(1+B$5*$B$3)))/2)))+Calculadora!$B$11*SQRT($A10*(1-$A10)+($A10*(1+B$5*$B$3))*(1-($A10*(1+B$5*$B$3)))))^2)/(($A10*(1+B$5*$B$3))-$A10)^2,0) -> 25172 | C10: =ROUNDUP(((Calculadora!$B$10*SQRT(2*(($A10+($A10*(1+C$5*$B$3)))/2)*(1-(($A10+($A10*(1+C$5*$B$3)))/2)))+Calculadora!$B$11*SQRT($A10*(1-$A10)+($A10*(1+C$5*$B$3))*(1-($A10*(1+C$5*$B$3)))))^2)/(($A10*(1+C$5*$B$3))-$A10)^2,0) -> 11429 | D10: =ROUNDUP(((Calculadora!$B$10*SQRT(2*(($A10+($A10*(1+D$5*$B$3)))/2)*(1-(($A10+($A10*(1+D$5*$B$3)))/2)))+Calculadora!$B$11*SQRT($A10*(1-$A10)+($A10*(1+D$5*$B$3))*(1-($A10*(1+D$5*$B$3)))))^2)/(($A10*(1+D$5*$B$3))-$A10)^2,0) -> 6563 | E10: =ROUNDUP(((Calculadora!$B$10*SQRT(2*(($A10+($A10*(1+E$5*$B$3)))/2)*(1-(($A10+($A10*(1+E$5*$B$3)))/2)))+Calculadora!$B$11*SQRT($A10*(1-$A10)+($A10*(1+E$5*$B$3))*(1-($A10*(1+E$5*$B$3)))))^2)/(($A10*(1+E$5*$B$3))-$A10)^2,0) -> 3036 | F10: =ROUNDUP(((Calculadora!$B$10*SQRT(2*(($A10+($A10*(1+F$5*$B$3)))/2)*(1-(($A10+($A10*(1+F$5*$B$3)))/2)))+Calculadora!$B$11*SQRT($A10*(1-$A10)+($A10*(1+F$5*$B$3))*(1-($A10*(1+F$5*$B$3)))))^2)/(($A10*(1+F$5*$B$3))-$A10)^2,0) -> 1177
A11: 0.1 | B11: =ROUNDUP(((Calculadora!$B$10*SQRT(2*(($A11+($A11*(1+B$5*$B$3)))/2)*(1-(($A11+($A11*(1+B$5*$B$3)))/2)))+Calculadora!$B$11*SQRT($A11*(1-$A11)+($A11*(1+B$5*$B$3))*(1-($A11*(1+B$5*$B$3)))))^2)/(($A11*(1+B$5*$B$3))-$A11)^2,0) -> 19676 | C11: =ROUNDUP(((Calculadora!$B$10*SQRT(2*(($A11+($A11*(1+C$5*$B$3)))/2)*(1-(($A11+($A11*(1+C$5*$B$3)))/2)))+Calculadora!$B$11*SQRT($A11*(1-$A11)+($A11*(1+C$5*$B$3))*(1-($A11*(1+C$5*$B$3)))))^2)/(($A11*(1+C$5*$B$3))-$A11)^2,0) -> 8928 | D11: =ROUNDUP(((Calculadora!$B$10*SQRT(2*(($A11+($A11*(1+D$5*$B$3)))/2)*(1-(($A11+($A11*(1+D$5*$B$3)))/2)))+Calculadora!$B$11*SQRT($A11*(1-$A11)+($A11*(1+D$5*$B$3))*(1-($A11*(1+D$5*$B$3)))))^2)/(($A11*(1+D$5*$B$3))-$A11)^2,0) -> 5124 | E11: =ROUNDUP(((Calculadora!$B$10*SQRT(2*(($A11+($A11*(1+E$5*$B$3)))/2)*(1-(($A11+($A11*(1+E$5*$B$3)))/2)))+Calculadora!$B$11*SQRT($A11*(1-$A11)+($A11*(1+E$5*$B$3))*(1-($A11*(1+E$5*$B$3)))))^2)/(($A11*(1+E$5*$B$3))-$A11)^2,0) -> 2367 | F11: =ROUNDUP(((Calculadora!$B$10*SQRT(2*(($A11+($A11*(1+F$5*$B$3)))/2)*(1-(($A11+($A11*(1+F$5*$B$3)))/2)))+Calculadora!$B$11*SQRT($A11*(1-$A11)+($A11*(1+F$5*$B$3))*(1-($A11*(1+F$5*$B$3)))))^2)/(($A11*(1+F$5*$B$3))-$A11)^2,0) -> 915
A12: 0.15 | B12: =ROUNDUP(((Calculadora!$B$10*SQRT(2*(($A12+($A12*(1+B$5*$B$3)))/2)*(1-(($A12+($A12*(1+B$5*$B$3)))/2)))+Calculadora!$B$11*SQRT($A12*(1-$A12)+($A12*(1+B$5*$B$3))*(1-($A12*(1+B$5*$B$3)))))^2)/(($A12*(1+B$5*$B$3))-$A12)^2,0) -> 12347 | C12: =ROUNDUP(((Calculadora!$B$10*SQRT(2*(($A12+($A12*(1+C$5*$B$3)))/2)*(1-(($A12+($A12*(1+C$5*$B$3)))/2)))+Calculadora!$B$11*SQRT($A12*(1-$A12)+($A12*(1+C$5*$B$3))*(1-($A12*(1+C$5*$B$3)))))^2)/(($A12*(1+C$5*$B$3))-$A12)^2,0) -> 5593 | D12: =ROUNDUP(((Calculadora!$B$10*SQRT(2*(($A12+($A12*(1+D$5*$B$3)))/2)*(1-(($A12+($A12*(1+D$5*$B$3)))/2)))+Calculadora!$B$11*SQRT($A12*(1-$A12)+($A12*(1+D$5*$B$3))*(1-($A12*(1+D$5*$B$3)))))^2)/(($A12*(1+D$5*$B$3))-$A12)^2,0) -> 3204 | E12: =ROUNDUP(((Calculadora!$B$10*SQRT(2*(($A12+($A12*(1+E$5*$B$3)))/2)*(1-(($A12+($A12*(1+E$5*$B$3)))/2)))+Calculadora!$B$11*SQRT($A12*(1-$A12)+($A12*(1+E$5*$B$3))*(1-($A12*(1+E$5*$B$3)))))^2)/(($A12*(1+E$5*$B$3))-$A12)^2,0) -> 1475 | F12: =ROUNDUP(((Calculadora!$B$10*SQRT(2*(($A12+($A12*(1+F$5*$B$3)))/2)*(1-(($A12+($A12*(1+F$5*$B$3)))/2)))+Calculadora!$B$11*SQRT($A12*(1-$A12)+($A12*(1+F$5*$B$3))*(1-($A12*(1+F$5*$B$3)))))^2)/(($A12*(1+F$5*$B$3))-$A12)^2,0) -> 566
A13: 0.2 | B13: =ROUNDUP(((Calculadora!$B$10*SQRT(2*(($A13+($A13*(1+B$5*$B$3)))/2)*(1-(($A13+($A13*(1+B$5*$B$3)))/2)))+Calculadora!$B$11*SQRT($A13*(1-$A13)+($A13*(1+B$5*$B$3))*(1-($A13*(1+B$5*$B$3)))))^2)/(($A13*(1+B$5*$B$3))-$A13)^2,0) -> 8683 | C13: =ROUNDUP(((Calculadora!$B$10*SQRT(2*(($A13+($A13*(1+C$5*$B$3)))/2)*(1-(($A13+($A13*(1+C$5*$B$3)))/2)))+Calculadora!$B$11*SQRT($A13*(1-$A13)+($A13*(1+C$5*$B$3))*(1-($A13*(1+C$5*$B$3)))))^2)/(($A13*(1+C$5*$B$3))-$A13)^2,0) -> 3926 | D13: =ROUNDUP(((Calculadora!$B$10*SQRT(2*(($A13+($A13*(1+D$5*$B$3)))/2)*(1-(($A13+($A13*(1+D$5*$B$3)))/2)))+Calculadora!$B$11*SQRT($A13*(1-$A13)+($A13*(1+D$5*$B$3))*(1-($A13*(1+D$5*$B$3)))))^2)/(($A13*(1+D$5*$B$3))-$A13)^2,0) -> 2245 | E13: =ROUNDUP(((Calculadora!$B$10*SQRT(2*(($A13+($A13*(1+E$5*$B$3)))/2)*(1-(($A13+($A13*(1+E$5*$B$3)))/2)))+Calculadora!$B$11*SQRT($A13*(1-$A13)+($A13*(1+E$5*$B$3))*(1-($A13*(1+E$5*$B$3)))))^2)/(($A13*(1+E$5*$B$3))-$A13)^2,0) -> 1029 | F13: =ROUNDUP(((Calculadora!$B$10*SQRT(2*(($A13+($A13*(1+F$5*$B$3)))/2)*(1-(($A13+($A13*(1+F$5*$B$3)))/2)))+Calculadora!$B$11*SQRT($A13*(1-$A13)+($A13*(1+F$5*$B$3))*(1-($A13*(1+F$5*$B$3)))))^2)/(($A13*(1+F$5*$B$3))-$A13)^2,0) -> 392
A15: Cada celda = usuarios por brazo (tratamiento o control), sin margen de pérdidas. Multiplica por 2 para el total del tier.

Sheet Instrucciones
A1: Cómo usar esta hoja (2 minutos)
A3: 1. En la hoja Calculadora, cambia las celdas azules con fondo amarillo. Los números actuales son ejemplos.
A4: 2. Parámetros generales: deja alpha 0.05 y poder 0.80 salvo que tengas otra regla. Pon en comparaciones cuántos tiers pruebas (3 si Excelente, Bueno y Bajo).
A5: 3. Por tier: tu TOPE de referidores (el máximo que existe), cuántos usuarios pones en TRATAMIENTO y cuántos en CONTROL (los escribes tú), loans nuevos al mes con 500 MXN, meses de ventana, lift esperado y take-up.
A6: 4. Lee primero 'PODER real con tus usuarios' y '¿Detecta el lift esperado?'. Esos números usan exactamente los usuarios que escribiste. La fila verde/roja te avisa si pasas el tope.
A7: 5. Si dice NO, mira 'Efecto mínimo detectable' (lo más chico que sí verías con tus usuarios) y 'Meses de ventana para llegar al poder'.
A8: 6. 'Referencia: lo que necesitarías' es solo para comparar contra tu tope. Si no cabe, no lo persigas: alarga la ventana, prueba menos tiers o espera un lift mayor.
A9: 7. La hoja Tabla_n da una rejilla de referencia: usuarios por brazo para cada tasa base y lift (50/50).
A11: De dónde sale cada dato:
A12: Tope: referidores activos del tier. Loans al mes: referidos con loan del tier en el último mes. Lift: tu hipótesis (qué mejora justificaría pagar más crédito).
A13: Take-up: de los que reciben el crédito, % que realmente lo usa. Si no lo tienes, prueba 100%, 60% y 40% para ver la sensibilidad.
A15: Nota: el tier Regular no cambia (se queda en 500), por eso no entra a la calculadora. Se usa como referencia de tendencia, no como control de los demás tiers.
